Workbook

Sheet Sheet1
A1: Công ty: CTY TNHH VINH GIA
A2: BẢNG CHẤM CÔNG THÁNG 4 NĂM 2026
A3: BỘ PHẬN/XƯỞNG: HC - NS
A4: STT | B4: MÃ NHÂN VIÊN | D4: HỌ VÀ TÊN | E4: Ngày Vào Làm | F4: Ngày Trong Tháng | AK4: Công Chính | AM4: Tăng Ca | AN4: Chủ Nhật | AO4: Tăng Ca Chủ Nhật | AP4: Ghi Chú
F5: 1 | G5: 2 | H5: 3 | I5: 4 | J5: 5 | K5: 6 | L5: 7 | M5: 8 | N5: 9 | O5: 10 | P5: 11 | Q5: 12 | R5: 13 | S5: 14 | T5: 15 | U5: 16 | V5: 17 | W5: 18 | X5: 19 | Y5: 20 | Z5: 21 | AA5: 22 | AB5: 23 | AC5: 24 | AD5: 25 | AE5: 26 | AF5: 27 | AG5: 28 | AH5: 29 | AI5: 30 | AJ5: 1
F6: T.4 | G6: T.5 | H6: T.6 | I6: T.7 | J6: CN | K6: T.2 | L6: T.3 | M6: T.4 | N6: T.5 | O6: T.6 | P6: T.7 | Q6: CN | R6: T.2 | S6: T.3 | T6: T.4 | U6: T.5 | V6: T.6 | W6: T.7 | X6: CN | Y6: T.2 | Z6: T.3 | AA6: T.4 | AB6: T.5 | AC6: T.6 | AD6: T.7 | AE6: CN | AF6: T.2 | AG6: T.3 | AH6: T.4 | AI6: T.5 | AJ6: T.6
A7: CAY XANH - TAP VU
A8: 1 | B8: VGCN00571 | C8: =AQ8 -> 0651000562600 | D8: Phạm Lượm | E8: 45461 | F8: 1 | G8: 1 | H8: 1 | I8: 1 | J8: CuT | K8: 1 | L8: 1 | M8: 1 | N8: 1 | O8: 1 | P8: 1 | Q8: CuT | R8: 1 | S8: 1 | T8: 1 | U8: 1 | V8: 1 | W8: 1 | X8: CuT | Y8: 1 | Z8: 1 | AA8: 1 | AB8: cđ | AC8: 1 | AD8: 1 | AE8: CuT | AG8: 1 | AH8: 1 | AK8: 23 | AL8: =SUM(F8:AJ8) -> 23 | AM8: 0 | AN8: 0 | AO8: 0 | AP8: =COUNTIF(F8:AJ8,"cđ") -> 1 | AQ8: =VLOOKUP(B8,Sheet2!$B$2:$C$519,2,0) -> 0651000562600
C9: =AQ9 -> #N/A | AL9: =SUM(F9:AJ9) -> 0 | AQ9: =VLOOKUP(B9,Sheet2!$B$2:$C$519,2,0) -> #N/A
A10: 3 | B10: VGCN00573 | C10: =AQ10 -> 0651000612781 | D10: Đỗ Thị Lệ Thúy | E10: 45461 | F10: 1 | G10: 1 | H10: 1 | I10: 1 | J10: CuT | K10: 1 | L10: 1 | M10: 1 | N10: 1 | O10: 1 | P10: 1 | Q10: CuT | R10: 1 | S10: 1 | T10: 1 | U10: 1 | V10: 1 | W10: 1 | X10: CuT | Y10: 1 | Z10: 1 | AA10: 1 | AB10: 1 | AC10: 1 | AD10: 1 | AE10: CuT | AG10: 1 | AH10: 1 | AK10: 24 | AL10: =SUM(F10:AJ10) -> 24 | AM10: 4.5 | AN10: 0 | AO10: 0 | AP10: =COUNTIF(F10:AJ10,"cđ") -> 0 | AQ10: =VLOOKUP(B10,Sheet2!$B$2:$C$519,2,0) -> 0651000612781
C11: =AQ11 -> #N/A | K11: 1.5 | R11: 1.5 | Y11: 1.5 | AL11: =SUM(F11:AJ11) -> 4.5 | AQ11: =VLOOKUP(B11,Sheet2!$B$2:$C$519,2,0) -> #N/A
A12: 4 | B12: VGCN00574 | C12: =AQ12 -> 0651000527446 | D12: Đoàn Thị Tỉnh | E12: 45461 | F12: 1 | G12: 1 | H12: 1 | I12: 1 | J12: CuT | K12: 1 | L12: 1 | M12: 1 | N12: 1 | O12: 1 | P12: 1 | Q12: CuT | R12: 1 | S12: 1 | T12: 1 | U12: 1 | V12: 1 | X12: CuT | Y12: 1 | Z12: 1 | AA12: 1 | AB12: 1 | AC12: 1 | AD12: 1 | AE12: CuT | AG12: 1 | AH12: 1 | AK12: 23 | AL12: =SUM(F12:AJ12) -> 23 | AM12: 4.5 | AN12: 0 | AO12: 0 | AP12: =COUNTIF(F12:AJ12,"cđ") -> 0 | AQ12: =VLOOKUP(B12,Sheet2!$B$2:$C$519,2,0) -> 0651000527446
C13: =AQ13 -> #N/A | K13: 1.5 | R13: 1.5 | Y13: 1.5 | AL13: =SUM(F13:AJ13) -> 4.5 | AQ13: =VLOOKUP(B13,Sheet2!$B$2:$C$519,2,0) -> #N/A
A14: 5 | B14: VGCN01049 | C14: =AQ14 -> 0001055960023 | D14: Nguyen Thi My Loi | E14: 45825 | F14: 1 | G14: 1 | H14: 1 | I14: 1 | J14: CuT | K14: 1 | L14: 1 | M14: 1 | N14: 1 | O14: 1 | P14: 1 | Q14: CuT | R14: 1 | S14: 1 | T14: 1 | U14: 1 | V14: 1 | W14: 1 | X14: CuT | Y14: 1 | Z14: 1 | AA14: 1 | AB14: 1 | AC14: 1 | AD14: 1 | AE14: CuT | AG14: 1 | AH14: 1 | AK14: 24 | AL14: =SUM(F14:AJ14) -> 24 | AM14: 6.5 | AN14: 0 | AO14: 0 | AP14: =COUNTIF(F14:AJ14,"cđ") -> 0 | AQ14: =VLOOKUP(B14,Sheet2!$B$2:$C$519,2,0) -> 0001055960023
C15: =AQ15 -> #N/A | K15: 1.5 | O15: 2 | R15: 1.5 | Y15: 1.5 | AL15: =SUM(F15:AJ15) -> 6.5 | AQ15: =VLOOKUP(B15,Sheet2!$B$2:$C$519,2,0) -> #N/A
A16: 6 | B16: VGCN01094 | C16: =AQ16 -> 0001040333611 | D16: Lương Thị Hương | E16: 45461 | F16: 1 | G16: 1 | H16: 1 | I16: 1 | J16: CuT | K16: 1 | L16: 1 | M16: 1 | N16: 1 | O16: 1 | P16: 1 | Q16: CuT | R16: 1 | S16: 1 | T16: 0.5 | U16: 1 | V16: 1 | W16: 1 | X16: CuT | Y16: 1 | Z16: 1 | AA16: 1 | AB16: 1 | AC16: 1 | AD16: 1 | AE16: CuT | AG16: 1 | AH16: 1 | AK16: 23.5 | AL16: =SUM(F16:AJ16) -> 23.5 | AM16: 6 | AN16: 0 | AO16: 0 | AP16: =COUNTIF(F16:AJ16,"cđ") -> 0 | AQ16: =VLOOKUP(B16,Sheet2!$B$2:$C$519,2,0) -> 0001040333611
C17: =AQ17 -> #N/A | K17: 1.5 | O17: 1.5 | R17: 1.5 | Y17: 1.5 | AL17: =SUM(F17:AJ17) -> 6 | AQ17: =VLOOKUP(B17,Sheet2!$B$2:$C$519,2,0) -> #N/A
A18: 7 | B18: VGCN01505 | C18: =AQ18 -> 0651000850315 | D18: Phan Van Tri | E18: 45584 | F18: 1 | G18: 1 | H18: 1 | I18: 1 | J18: CuT | K18: 1 | L18: 1 | M18: 1 | N18: 1 | O18: 1 | P18: 1 | Q18: CuT | R18: 1 | S18: 1 | T18: 1 | U18: 1 | V18: 1 | W18: 1 | X18: CuT | Y18: 1 | AA18: 1 | AB18: 1 | AC18: 1 | AD18: 1 | AE18: CuT | AG18: 1 | AH18: 1 | AK18: 23 | AL18: =SUM(F18:AJ18) -> 23 | AM18: 0 | AN18: 0 | AO18: 0 | AP18: =COUNTIF(F18:AJ18,"cđ") -> 0 | AQ18: =VLOOKUP(B18,Sheet2!$B$2:$C$519,2,0) -> 0651000850315
C19: =AQ19 -> #N/A | AL19: =SUM(F19:AJ19) -> 0 | AQ19: =VLOOKUP(B19,Sheet2!$B$2:$C$519,2,0) -> #N/A
A20: TỔNG CỘNG | AK20: =SUM(AK8:AK19) -> 140.5 | AL20: =SUM(AL8:AL19) -> 162 | AM20: =SUM(AM8:AM19) -> 21.5 | AN20: =SUM(AN8:AN19) -> 0 | AO20: =SUM(AO8:AO19) -> 0 | AP20: =SUM(AP8:AP19) -> 1 | AQ20: =VLOOKUP(B20,Sheet2!$B$2:$C$519,2,0) -> #N/A
B23: BAN GIÁM ĐỐC | P23: GIÁM ĐỐC SẢN XUẤT | AK23: NGƯỜI CHẤM CÔNG

Sheet Sheet2
B2: VGCN00259 | C2: 0651000613032 | D2: Huỳnh Xuân Đoàn | E2: 4910004929
B3: VGCN00335 | C3: 0651000455836 | D3: Nguyễn Thị Diễm Kiều | E3: 4910004940
B4: VGCN00548 | C4: 0651000613050 | D4: Hoàng Vinh | E4: 4910004945
B5: VGCN00284 | C5: 0651000612525 | D5: Nguyễn Thị Thu Nga | E5: 4910004956
B6: VGCN00154 | C6: 0651000612567 | D6: Tạ Minh | E6: 4910004964
B7: VGCN00698 | C7: 0651000612479 | D7: Lê Đông | E7: 4910004970
B8: VGCN00467 | C8: 0651000613048 | D8: Trần Thị Lạc | E8: 4910012215
B9: VGCN00032 | C9: 0651000612780 | D9: Ngô Thị Lệ Thương | E9: 4910012229
B10: VGCN00341 | C10: 0651000612582 | D10: Nguyễn Thị Đào | E10: 4910012230
B11: VGCN00479 | C11: 0651000612439 | D11: Bùi Thị Tí | E11: 4910012236
B12: VGCN00071 | C12: 0651000613395 | D12: Hoàng Minh Dũng | E12: 4910012238
B13: VGCN00499 | C13: 0651000612416 | D13: Nguyễn Thị Thái | E13: 4910012244
... B40: VGCN00574 | C40: 0651000527446 | D40: Đoàn Thị Tỉnh | E40: 4910012074
B41: VGCN00223 | C41: 0651000621072 | D41: Trần Thị Thu Thùy | E41: 0406005713
B42: VGCN00554 | C42: 0651000613242 | D42: Trần Thị Thêm | E42: 4912002184
B43: VGCN00372 | C43: 0651000613195 | D43: Phạm Thị Dung | E43: 4912002188
B44: VGCN00085 | C44: 0651000614945 | D44: Trần Thị Kim Cương | E44: 4912002187
B45: VGCN00399 | C45: 0651000613226 | D45: Nguyễn Thị Thùy Dương | E45: 4912002196
B46: VGCN00377 | C46: 0651000614017 | D46: Lê Thị Thu Thủy | E46: 4912002190
B47: VGCN00535 | C47: 0651000613460 | D47: Nguyễn Thị Minh Ly | E47: 4912002212
B48: VGCN00425 | C48: 0651000613168 | D48: Bùi Xuân Sữu | E48: 4912002213
B49: VGCN00137 | C49: 0651000612695 | D49: Bùi Cự | E49: 4912007650
B50: VGCN00521 | C50: 0651000612757 | D50: Bùi Thị Thùy Thủy | E50: 4912007654
B51: VGCN00573 | C51: 0651000612781 | D51: Đỗ Thị Lệ Thúy | E51: 4912007657
B52: VGCN00151 | C52: 0651000613060 | D52: Phan Thị Mỹ | E52: 4912007658
B53: VGCN00030 | C53: 0651000623358 | D53: Nguyễn Xuân Vũ | E53: 4913012660
... B159: VGCN00232 | C159: 0651000629637 | D159: Đinh Văn Sự | E159: 4921304165
B160: VGCN00267 | C160: 0651000827976 | D160: Nguyễn Thị Sương | E160: 0207099992
B161: VGCN00281 | C161: 0651000813509 | D161: Nguyễn Thị Thu Yến | E161: 4921309356
B162: VGCN00307 | C162: 0651000786725 | D162: Phạm Thị Phú | E162: 4921297597
B163: VGCN00354 | C163: 0651000765015 | D163: Ngô Thanh Phương | E163: 4921399309
B164: VGCN00292 | C164: 0001015366212 | D164: Dương Thị Phương | E164: 7914151860
B165: VGCN00584 | C165: 0651000856769 | D165: Nguyễn Thị Mỹ Long | E165: 4921313783
B166: VGCN00003 | C166: 0651000843456 | D166: Bùi Thế Ngôn | E166: 4921358798
B167: VGCN00640 | C167: 0001017145310 | D167: Nguyễn Minh Hạnh | E167: 4921284410
B168: VGCN00009 | C168: 0651000613077 | D168: Bùi Thạch | E168: 4910012224
B169: VGCN00336 | C169: 0651000860002 | D169: Nguyễn Đức Cảnh | E169: 4921310379
B170: VGCN00567 | C170: 0651000617816 | D170: Phan Thị Quít | E170: 4921717640
B171: VGCN00538 | C171: 0651000857874 | D171: Chung Thị Liên | E171: 4921308331
B172: VGCN00381 | C172: 0651000790310 | D172: Huỳnh Thị Dương | E172: 4921896339
...
